2023-09-16 08:13:42,095 INFO    MainThread:11396 [wandb_setup.py:_flush():76] Current SDK version is 0.15.10
2023-09-16 08:13:42,095 INFO    MainThread:11396 [wandb_setup.py:_flush():76] Configure stats pid to 11396
2023-09-16 08:13:42,095 INFO    MainThread:11396 [wandb_setup.py:_flush():76] Loading settings from C:\Users\calle\.config\wandb\settings
2023-09-16 08:13:42,095 INFO    MainThread:11396 [wandb_setup.py:_flush():76] Loading settings from c:\Users\calle\Documents\GitHub\robust-rl\cliff_car\wandb\settings
2023-09-16 08:13:42,095 INFO    MainThread:11396 [wandb_setup.py:_flush():76] Loading settings from environment variables: {}
2023-09-16 08:13:42,095 INFO    MainThread:11396 [wandb_setup.py:_flush():76] Inferring run settings from compute environment: {'program_relpath': 'cliff_car\\cliff_car_experiments.py', 'program': 'c:\\Users\\calle\\Documents\\GitHub\\robust-rl\\cliff_car\\cliff_car_experiments.py'}
2023-09-16 08:13:42,095 INFO    MainThread:11396 [wandb_setup.py:_flush():76] Applying login settings: {'api_key': '***REDACTED***'}
2023-09-16 08:13:42,095 INFO    MainThread:11396 [wandb_setup.py:_flush():76] Applying login settings: {'api_key': '***REDACTED***'}
2023-09-16 08:13:42,096 INFO    MainThread:11396 [wandb_init.py:_log_setup():524] Logging user logs to c:\Users\calle\Documents\GitHub\robust-rl\cliff_car\wandb\run-20230916_081342-e3nu31vx\logs\debug.log
2023-09-16 08:13:42,096 INFO    MainThread:11396 [wandb_init.py:_log_setup():525] Logging internal logs to c:\Users\calle\Documents\GitHub\robust-rl\cliff_car\wandb\run-20230916_081342-e3nu31vx\logs\debug-internal.log
2023-09-16 08:13:42,096 INFO    MainThread:11396 [wandb_init.py:init():564] calling init triggers
2023-09-16 08:13:42,096 INFO    MainThread:11396 [wandb_init.py:init():571] wandb.init called with sweep_config: {}
config: {'delta': 0.01, 'linear': False, 'factor': 1, 'seed': 1002, 'robust_batch_size': 100, 'fineness': 2, 'ripe_when': None, 'ready_when': 10, 'num_neighbours': 2, 'bin_size': 200, 'train_frames': 5000, 'grad_batch_size': 10, 'replay_buffer_size': 1000, 'epsilon_decay': 0.0004, 'noise_var': [[0.05, 0], [0, 0.05]], 'noise_mean': [0, 0]}
2023-09-16 08:13:42,096 INFO    MainThread:11396 [wandb_init.py:init():614] starting backend
2023-09-16 08:13:42,096 INFO    MainThread:11396 [wandb_init.py:init():618] setting up manager
2023-09-16 08:13:42,098 INFO    MainThread:11396 [backend.py:_multiprocessing_setup():105] multiprocessing start_methods=spawn, using: spawn
2023-09-16 08:13:42,100 INFO    MainThread:11396 [wandb_init.py:init():624] backend started and connected
2023-09-16 08:13:42,104 INFO    MainThread:11396 [wandb_init.py:init():715] updated telemetry
2023-09-16 08:13:42,142 INFO    MainThread:11396 [wandb_init.py:init():748] communicating run to backend with 90.0 second timeout
2023-09-16 08:13:47,314 INFO    Thread-7 (wrapped_target):11396 [retry.py:__call__():172] Retry attempt failed:
Traceback (most recent call last):
  File "C:\Users\calle\Anaconda3\envs\bachelor\Lib\site-packages\urllib3\connection.py", line 203, in _new_conn
    sock = connection.create_connection(
           ^^^^^^^^^^^^^^^^^^^^^^^^^^^^^
  File "C:\Users\calle\Anaconda3\envs\bachelor\Lib\site-packages\urllib3\util\connection.py", line 60, in create_connection
    for res in socket.getaddrinfo(host, port, family, socket.SOCK_STREAM):
               ^^^^^^^^^^^^^^^^^^^^^^^^^^^^^^^^^^^^^^^^^^^^^^^^^^^^^^^^^^
  File "C:\Users\calle\Anaconda3\envs\bachelor\Lib\socket.py", line 962, in getaddrinfo
    for res in _socket.getaddrinfo(host, port, family, type, proto, flags):
               ^^^^^^^^^^^^^^^^^^^^^^^^^^^^^^^^^^^^^^^^^^^^^^^^^^^^^^^^^^^
socket.gaierror: [Errno 11001] getaddrinfo failed

The above exception was the direct cause of the following exception:

Traceback (most recent call last):
  File "C:\Users\calle\Anaconda3\envs\bachelor\Lib\site-packages\urllib3\connectionpool.py", line 790, in urlopen
    response = self._make_request(
               ^^^^^^^^^^^^^^^^^^^
  File "C:\Users\calle\Anaconda3\envs\bachelor\Lib\site-packages\urllib3\connectionpool.py", line 491, in _make_request
    raise new_e
  File "C:\Users\calle\Anaconda3\envs\bachelor\Lib\site-packages\urllib3\connectionpool.py", line 467, in _make_request
    self._validate_conn(conn)
  File "C:\Users\calle\Anaconda3\envs\bachelor\Lib\site-packages\urllib3\connectionpool.py", line 1092, in _validate_conn
    conn.connect()
  File "C:\Users\calle\Anaconda3\envs\bachelor\Lib\site-packages\urllib3\connection.py", line 611, in connect
    self.sock = sock = self._new_conn()
                       ^^^^^^^^^^^^^^^^
  File "C:\Users\calle\Anaconda3\envs\bachelor\Lib\site-packages\urllib3\connection.py", line 210, in _new_conn
    raise NameResolutionError(self.host, self, e) from e
urllib3.exceptions.NameResolutionError: <urllib3.connection.HTTPSConnection object at 0x00000256BFCDC490>: Failed to resolve 'api.wandb.ai' ([Errno 11001] getaddrinfo failed)

The above exception was the direct cause of the following exception:

Traceback (most recent call last):
  File "C:\Users\calle\Anaconda3\envs\bachelor\Lib\site-packages\requests\adapters.py", line 486, in send
    resp = conn.urlopen(
           ^^^^^^^^^^^^^
  File "C:\Users\calle\Anaconda3\envs\bachelor\Lib\site-packages\urllib3\connectionpool.py", line 844, in urlopen
    retries = retries.increment(
              ^^^^^^^^^^^^^^^^^^
  File "C:\Users\calle\Anaconda3\envs\bachelor\Lib\site-packages\urllib3\util\retry.py", line 515, in increment
    raise MaxRetryError(_pool, url, reason) from reason  # type: ignore[arg-type]
    ^^^^^^^^^^^^^^^^^^^^^^^^^^^^^^^^^^^^^^^^^^^^^^^^^^^
urllib3.exceptions.MaxRetryError: HTTPSConnectionPool(host='api.wandb.ai', port=443): Max retries exceeded with url: /graphql (Caused by NameResolutionError("<urllib3.connection.HTTPSConnection object at 0x00000256BFCDC490>: Failed to resolve 'api.wandb.ai' ([Errno 11001] getaddrinfo failed)"))

During handling of the above exception, another exception occurred:

Traceback (most recent call last):
  File "C:\Users\calle\Anaconda3\envs\bachelor\Lib\site-packages\wandb\sdk\lib\retry.py", line 131, in __call__
    result = self._call_fn(*args, **kwargs)
             ^^^^^^^^^^^^^^^^^^^^^^^^^^^^^^
  File "C:\Users\calle\Anaconda3\envs\bachelor\Lib\site-packages\wandb\sdk\internal\internal_api.py", line 358, in execute
    return self.client.execute(*args, **kwargs)  # type: ignore
           ^^^^^^^^^^^^^^^^^^^^^^^^^^^^^^^^^^^^
  File "C:\Users\calle\Anaconda3\envs\bachelor\Lib\site-packages\wandb\vendor\gql-0.2.0\wandb_gql\client.py", line 52, in execute
    result = self._get_result(document, *args, **kwargs)
             ^^^^^^^^^^^^^^^^^^^^^^^^^^^^^^^^^^^^^^^^^^^
  File "C:\Users\calle\Anaconda3\envs\bachelor\Lib\site-packages\wandb\vendor\gql-0.2.0\wandb_gql\client.py", line 60, in _get_result
    return self.transport.execute(document, *args, **kwargs)
           ^^^^^^^^^^^^^^^^^^^^^^^^^^^^^^^^^^^^^^^^^^^^^^^^^
  File "C:\Users\calle\Anaconda3\envs\bachelor\Lib\site-packages\wandb\sdk\lib\gql_request.py", line 55, in execute
    request = self.session.post(self.url, **post_args)
              ^^^^^^^^^^^^^^^^^^^^^^^^^^^^^^^^^^^^^^^^
  File "C:\Users\calle\Anaconda3\envs\bachelor\Lib\site-packages\requests\sessions.py", line 637, in post
    return self.request("POST", url, data=data, json=json, **kwargs)
           ^^^^^^^^^^^^^^^^^^^^^^^^^^^^^^^^^^^^^^^^^^^^^^^^^^^^^^^^^
  File "C:\Users\calle\Anaconda3\envs\bachelor\Lib\site-packages\requests\sessions.py", line 589, in request
    resp = self.send(prep, **send_kwargs)
           ^^^^^^^^^^^^^^^^^^^^^^^^^^^^^^
  File "C:\Users\calle\Anaconda3\envs\bachelor\Lib\site-packages\requests\sessions.py", line 703, in send
    r = adapter.send(request, **kwargs)
        ^^^^^^^^^^^^^^^^^^^^^^^^^^^^^^^
  File "C:\Users\calle\Anaconda3\envs\bachelor\Lib\site-packages\requests\adapters.py", line 519, in send
    raise ConnectionError(e, request=request)
requests.exceptions.ConnectionError: HTTPSConnectionPool(host='api.wandb.ai', port=443): Max retries exceeded with url: /graphql (Caused by NameResolutionError("<urllib3.connection.HTTPSConnection object at 0x00000256BFCDC490>: Failed to resolve 'api.wandb.ai' ([Errno 11001] getaddrinfo failed)"))
2023-09-16 08:13:47,393 INFO    Thread-8 (wrapped_target):11396 [retry.py:__call__():172] Retry attempt failed:
Traceback (most recent call last):
  File "C:\Users\calle\Anaconda3\envs\bachelor\Lib\site-packages\urllib3\connection.py", line 203, in _new_conn
    sock = connection.create_connection(
           ^^^^^^^^^^^^^^^^^^^^^^^^^^^^^
  File "C:\Users\calle\Anaconda3\envs\bachelor\Lib\site-packages\urllib3\util\connection.py", line 60, in create_connection
    for res in socket.getaddrinfo(host, port, family, socket.SOCK_STREAM):
               ^^^^^^^^^^^^^^^^^^^^^^^^^^^^^^^^^^^^^^^^^^^^^^^^^^^^^^^^^^
  File "C:\Users\calle\Anaconda3\envs\bachelor\Lib\socket.py", line 962, in getaddrinfo
    for res in _socket.getaddrinfo(host, port, family, type, proto, flags):
               ^^^^^^^^^^^^^^^^^^^^^^^^^^^^^^^^^^^^^^^^^^^^^^^^^^^^^^^^^^^
socket.gaierror: [Errno 11001] getaddrinfo failed

The above exception was the direct cause of the following exception:

Traceback (most recent call last):
  File "C:\Users\calle\Anaconda3\envs\bachelor\Lib\site-packages\urllib3\connectionpool.py", line 790, in urlopen
    response = self._make_request(
               ^^^^^^^^^^^^^^^^^^^
  File "C:\Users\calle\Anaconda3\envs\bachelor\Lib\site-packages\urllib3\connectionpool.py", line 491, in _make_request
    raise new_e
  File "C:\Users\calle\Anaconda3\envs\bachelor\Lib\site-packages\urllib3\connectionpool.py", line 467, in _make_request
    self._validate_conn(conn)
  File "C:\Users\calle\Anaconda3\envs\bachelor\Lib\site-packages\urllib3\connectionpool.py", line 1092, in _validate_conn
    conn.connect()
  File "C:\Users\calle\Anaconda3\envs\bachelor\Lib\site-packages\urllib3\connection.py", line 611, in connect
    self.sock = sock = self._new_conn()
                       ^^^^^^^^^^^^^^^^
  File "C:\Users\calle\Anaconda3\envs\bachelor\Lib\site-packages\urllib3\connection.py", line 210, in _new_conn
    raise NameResolutionError(self.host, self, e) from e
urllib3.exceptions.NameResolutionError: <urllib3.connection.HTTPSConnection object at 0x00000256BDA09410>: Failed to resolve 'api.wandb.ai' ([Errno 11001] getaddrinfo failed)

The above exception was the direct cause of the following exception:

Traceback (most recent call last):
  File "C:\Users\calle\Anaconda3\envs\bachelor\Lib\site-packages\requests\adapters.py", line 486, in send
    resp = conn.urlopen(
           ^^^^^^^^^^^^^
  File "C:\Users\calle\Anaconda3\envs\bachelor\Lib\site-packages\urllib3\connectionpool.py", line 844, in urlopen
    retries = retries.increment(
              ^^^^^^^^^^^^^^^^^^
  File "C:\Users\calle\Anaconda3\envs\bachelor\Lib\site-packages\urllib3\util\retry.py", line 515, in increment
    raise MaxRetryError(_pool, url, reason) from reason  # type: ignore[arg-type]
    ^^^^^^^^^^^^^^^^^^^^^^^^^^^^^^^^^^^^^^^^^^^^^^^^^^^
urllib3.exceptions.MaxRetryError: HTTPSConnectionPool(host='api.wandb.ai', port=443): Max retries exceeded with url: /graphql (Caused by NameResolutionError("<urllib3.connection.HTTPSConnection object at 0x00000256BDA09410>: Failed to resolve 'api.wandb.ai' ([Errno 11001] getaddrinfo failed)"))

During handling of the above exception, another exception occurred:

Traceback (most recent call last):
  File "C:\Users\calle\Anaconda3\envs\bachelor\Lib\site-packages\wandb\sdk\lib\retry.py", line 131, in __call__
    result = self._call_fn(*args, **kwargs)
             ^^^^^^^^^^^^^^^^^^^^^^^^^^^^^^
  File "C:\Users\calle\Anaconda3\envs\bachelor\Lib\site-packages\wandb\sdk\internal\internal_api.py", line 358, in execute
    return self.client.execute(*args, **kwargs)  # type: ignore
           ^^^^^^^^^^^^^^^^^^^^^^^^^^^^^^^^^^^^
  File "C:\Users\calle\Anaconda3\envs\bachelor\Lib\site-packages\wandb\vendor\gql-0.2.0\wandb_gql\client.py", line 52, in execute
    result = self._get_result(document, *args, **kwargs)
             ^^^^^^^^^^^^^^^^^^^^^^^^^^^^^^^^^^^^^^^^^^^
  File "C:\Users\calle\Anaconda3\envs\bachelor\Lib\site-packages\wandb\vendor\gql-0.2.0\wandb_gql\client.py", line 60, in _get_result
    return self.transport.execute(document, *args, **kwargs)
           ^^^^^^^^^^^^^^^^^^^^^^^^^^^^^^^^^^^^^^^^^^^^^^^^^
  File "C:\Users\calle\Anaconda3\envs\bachelor\Lib\site-packages\wandb\sdk\lib\gql_request.py", line 55, in execute
    request = self.session.post(self.url, **post_args)
              ^^^^^^^^^^^^^^^^^^^^^^^^^^^^^^^^^^^^^^^^
  File "C:\Users\calle\Anaconda3\envs\bachelor\Lib\site-packages\requests\sessions.py", line 637, in post
    return self.request("POST", url, data=data, json=json, **kwargs)
           ^^^^^^^^^^^^^^^^^^^^^^^^^^^^^^^^^^^^^^^^^^^^^^^^^^^^^^^^^
  File "C:\Users\calle\Anaconda3\envs\bachelor\Lib\site-packages\requests\sessions.py", line 589, in request
    resp = self.send(prep, **send_kwargs)
           ^^^^^^^^^^^^^^^^^^^^^^^^^^^^^^
  File "C:\Users\calle\Anaconda3\envs\bachelor\Lib\site-packages\requests\sessions.py", line 703, in send
    r = adapter.send(request, **kwargs)
        ^^^^^^^^^^^^^^^^^^^^^^^^^^^^^^^
  File "C:\Users\calle\Anaconda3\envs\bachelor\Lib\site-packages\requests\adapters.py", line 519, in send
    raise ConnectionError(e, request=request)
requests.exceptions.ConnectionError: HTTPSConnectionPool(host='api.wandb.ai', port=443): Max retries exceeded with url: /graphql (Caused by NameResolutionError("<urllib3.connection.HTTPSConnection object at 0x00000256BDA09410>: Failed to resolve 'api.wandb.ai' ([Errno 11001] getaddrinfo failed)"))
2023-09-16 08:15:12,742 ERROR   MainThread:11396 [wandb_init.py:init():774] encountered error: Run initialization has timed out after 90.0 sec. 
Please refer to the documentation for additional information: https://docs.wandb.ai/guides/track/tracking-faq#initstarterror-error-communicating-with-wandb-process-
2023-09-16 08:15:14,764 ERROR   MainThread:11396 [wandb_init.py:init():1183] Run initialization has timed out after 90.0 sec. 
Please refer to the documentation for additional information: https://docs.wandb.ai/guides/track/tracking-faq#initstarterror-error-communicating-with-wandb-process-
Traceback (most recent call last):
  File "C:\Users\calle\Anaconda3\envs\bachelor\Lib\site-packages\wandb\sdk\wandb_init.py", line 1165, in init
    run = wi.init()
          ^^^^^^^^^
  File "C:\Users\calle\Anaconda3\envs\bachelor\Lib\site-packages\wandb\sdk\wandb_init.py", line 780, in init
    raise error
wandb.errors.CommError: Run initialization has timed out after 90.0 sec. 
Please refer to the documentation for additional information: https://docs.wandb.ai/guides/track/tracking-faq#initstarterror-error-communicating-with-wandb-process-
2023-09-16 08:15:15,781 WARNING MsgRouterThr:11396 [router.py:message_loop():77] message_loop has been closed
