2023-09-16 08:13:42,099 INFO    StreamThr :9248 [internal.py:wandb_internal():86] W&B internal server running at pid: 9248, started at: 2023-09-16 08:13:42.099988
2023-09-16 08:13:42,100 DEBUG   HandlerThread:9248 [handler.py:handle_request():144] handle_request: status
2023-09-16 08:13:42,104 INFO    WriterThread:9248 [datastore.py:open_for_write():85] open: c:\Users\calle\Documents\GitHub\robust-rl\cliff_car\wandb\run-20230916_081342-e3nu31vx\run-e3nu31vx.wandb
2023-09-16 08:13:42,105 DEBUG   SenderThread:9248 [sender.py:send():379] send: header
2023-09-16 08:13:42,143 DEBUG   SenderThread:9248 [sender.py:send():379] send: run
2023-09-16 08:13:45,664 INFO    SenderThread:9248 [retry.py:__call__():172] Retry attempt failed:
Traceback (most recent call last):
  File "C:\Users\calle\Anaconda3\envs\bachelor\Lib\site-packages\urllib3\connection.py", line 203, in _new_conn
    sock = connection.create_connection(
           ^^^^^^^^^^^^^^^^^^^^^^^^^^^^^
  File "C:\Users\calle\Anaconda3\envs\bachelor\Lib\site-packages\urllib3\util\connection.py", line 60, in create_connection
    for res in socket.getaddrinfo(host, port, family, socket.SOCK_STREAM):
               ^^^^^^^^^^^^^^^^^^^^^^^^^^^^^^^^^^^^^^^^^^^^^^^^^^^^^^^^^^
  File "C:\Users\calle\Anaconda3\envs\bachelor\Lib\socket.py", line 962, in getaddrinfo
    for res in _socket.getaddrinfo(host, port, family, type, proto, flags):
               ^^^^^^^^^^^^^^^^^^^^^^^^^^^^^^^^^^^^^^^^^^^^^^^^^^^^^^^^^^^
socket.gaierror: [Errno 11001] getaddrinfo failed

The above exception was the direct cause of the following exception:

Traceback (most recent call last):
  File "C:\Users\calle\Anaconda3\envs\bachelor\Lib\site-packages\urllib3\connectionpool.py", line 790, in urlopen
    response = self._make_request(
               ^^^^^^^^^^^^^^^^^^^
  File "C:\Users\calle\Anaconda3\envs\bachelor\Lib\site-packages\urllib3\connectionpool.py", line 491, in _make_request
    raise new_e
  File "C:\Users\calle\Anaconda3\envs\bachelor\Lib\site-packages\urllib3\connectionpool.py", line 467, in _make_request
    self._validate_conn(conn)
  File "C:\Users\calle\Anaconda3\envs\bachelor\Lib\site-packages\urllib3\connectionpool.py", line 1092, in _validate_conn
    conn.connect()
  File "C:\Users\calle\Anaconda3\envs\bachelor\Lib\site-packages\urllib3\connection.py", line 611, in connect
    self.sock = sock = self._new_conn()
                       ^^^^^^^^^^^^^^^^
  File "C:\Users\calle\Anaconda3\envs\bachelor\Lib\site-packages\urllib3\connection.py", line 210, in _new_conn
    raise NameResolutionError(self.host, self, e) from e
urllib3.exceptions.NameResolutionError: <urllib3.connection.HTTPSConnection object at 0x000001F5F13F95D0>: Failed to resolve 'api.wandb.ai' ([Errno 11001] getaddrinfo failed)

The above exception was the direct cause of the following exception:

Traceback (most recent call last):
  File "C:\Users\calle\Anaconda3\envs\bachelor\Lib\site-packages\requests\adapters.py", line 486, in send
    resp = conn.urlopen(
           ^^^^^^^^^^^^^
  File "C:\Users\calle\Anaconda3\envs\bachelor\Lib\site-packages\urllib3\connectionpool.py", line 844, in urlopen
    retries = retries.increment(
              ^^^^^^^^^^^^^^^^^^
  File "C:\Users\calle\Anaconda3\envs\bachelor\Lib\site-packages\urllib3\util\retry.py", line 515, in increment
    raise MaxRetryError(_pool, url, reason) from reason  # type: ignore[arg-type]
    ^^^^^^^^^^^^^^^^^^^^^^^^^^^^^^^^^^^^^^^^^^^^^^^^^^^
urllib3.exceptions.MaxRetryError: HTTPSConnectionPool(host='api.wandb.ai', port=443): Max retries exceeded with url: /graphql (Caused by NameResolutionError("<urllib3.connection.HTTPSConnection object at 0x000001F5F13F95D0>: Failed to resolve 'api.wandb.ai' ([Errno 11001] getaddrinfo failed)"))

During handling of the above exception, another exception occurred:

Traceback (most recent call last):
  File "C:\Users\calle\Anaconda3\envs\bachelor\Lib\site-packages\wandb\sdk\lib\retry.py", line 131, in __call__
    result = self._call_fn(*args, **kwargs)
             ^^^^^^^^^^^^^^^^^^^^^^^^^^^^^^
  File "C:\Users\calle\Anaconda3\envs\bachelor\Lib\site-packages\wandb\sdk\internal\internal_api.py", line 358, in execute
    return self.client.execute(*args, **kwargs)  # type: ignore
           ^^^^^^^^^^^^^^^^^^^^^^^^^^^^^^^^^^^^
  File "C:\Users\calle\Anaconda3\envs\bachelor\Lib\site-packages\wandb\vendor\gql-0.2.0\wandb_gql\client.py", line 52, in execute
    result = self._get_result(document, *args, **kwargs)
             ^^^^^^^^^^^^^^^^^^^^^^^^^^^^^^^^^^^^^^^^^^^
  File "C:\Users\calle\Anaconda3\envs\bachelor\Lib\site-packages\wandb\vendor\gql-0.2.0\wandb_gql\client.py", line 60, in _get_result
    return self.transport.execute(document, *args, **kwargs)
           ^^^^^^^^^^^^^^^^^^^^^^^^^^^^^^^^^^^^^^^^^^^^^^^^^
  File "C:\Users\calle\Anaconda3\envs\bachelor\Lib\site-packages\wandb\sdk\lib\gql_request.py", line 55, in execute
    request = self.session.post(self.url, **post_args)
              ^^^^^^^^^^^^^^^^^^^^^^^^^^^^^^^^^^^^^^^^
  File "C:\Users\calle\Anaconda3\envs\bachelor\Lib\site-packages\requests\sessions.py", line 637, in post
    return self.request("POST", url, data=data, json=json, **kwargs)
           ^^^^^^^^^^^^^^^^^^^^^^^^^^^^^^^^^^^^^^^^^^^^^^^^^^^^^^^^^
  File "C:\Users\calle\Anaconda3\envs\bachelor\Lib\site-packages\requests\sessions.py", line 589, in request
    resp = self.send(prep, **send_kwargs)
           ^^^^^^^^^^^^^^^^^^^^^^^^^^^^^^
  File "C:\Users\calle\Anaconda3\envs\bachelor\Lib\site-packages\requests\sessions.py", line 703, in send
    r = adapter.send(request, **kwargs)
        ^^^^^^^^^^^^^^^^^^^^^^^^^^^^^^^
  File "C:\Users\calle\Anaconda3\envs\bachelor\Lib\site-packages\requests\adapters.py", line 519, in send
    raise ConnectionError(e, request=request)
requests.exceptions.ConnectionError: HTTPSConnectionPool(host='api.wandb.ai', port=443): Max retries exceeded with url: /graphql (Caused by NameResolutionError("<urllib3.connection.HTTPSConnection object at 0x000001F5F13F95D0>: Failed to resolve 'api.wandb.ai' ([Errno 11001] getaddrinfo failed)"))
2023-09-16 08:13:47,189 DEBUG   HandlerThread:9248 [handler.py:handle_request():144] handle_request: keepalive
2023-09-16 08:13:52,224 DEBUG   HandlerThread:9248 [handler.py:handle_request():144] handle_request: keepalive
2023-09-16 08:13:57,248 DEBUG   HandlerThread:9248 [handler.py:handle_request():144] handle_request: keepalive
2023-09-16 08:14:02,269 DEBUG   HandlerThread:9248 [handler.py:handle_request():144] handle_request: keepalive
2023-09-16 08:14:07,293 DEBUG   HandlerThread:9248 [handler.py:handle_request():144] handle_request: keepalive
2023-09-16 08:14:12,312 DEBUG   HandlerThread:9248 [handler.py:handle_request():144] handle_request: keepalive
2023-09-16 08:14:17,341 DEBUG   HandlerThread:9248 [handler.py:handle_request():144] handle_request: keepalive
2023-09-16 08:14:22,365 DEBUG   HandlerThread:9248 [handler.py:handle_request():144] handle_request: keepalive
2023-09-16 08:14:27,418 DEBUG   HandlerThread:9248 [handler.py:handle_request():144] handle_request: keepalive
2023-09-16 08:14:32,450 DEBUG   HandlerThread:9248 [handler.py:handle_request():144] handle_request: keepalive
2023-09-16 08:14:37,486 DEBUG   HandlerThread:9248 [handler.py:handle_request():144] handle_request: keepalive
2023-09-16 08:14:42,525 DEBUG   HandlerThread:9248 [handler.py:handle_request():144] handle_request: keepalive
2023-09-16 08:14:47,555 DEBUG   HandlerThread:9248 [handler.py:handle_request():144] handle_request: keepalive
2023-09-16 08:14:52,594 DEBUG   HandlerThread:9248 [handler.py:handle_request():144] handle_request: keepalive
2023-09-16 08:14:57,649 DEBUG   HandlerThread:9248 [handler.py:handle_request():144] handle_request: keepalive
2023-09-16 08:15:02,685 DEBUG   HandlerThread:9248 [handler.py:handle_request():144] handle_request: keepalive
2023-09-16 08:15:07,727 DEBUG   HandlerThread:9248 [handler.py:handle_request():144] handle_request: keepalive
2023-09-16 08:15:12,742 DEBUG   HandlerThread:9248 [handler.py:handle_request():144] handle_request: cancel
2023-09-16 08:15:12,742 DEBUG   HandlerThread:9248 [handler.py:handle_request():144] handle_request: cancel
2023-09-16 08:15:14,767 DEBUG   HandlerThread:9248 [handler.py:handle_request():144] handle_request: shutdown
2023-09-16 08:15:14,767 INFO    HandlerThread:9248 [handler.py:finish():840] shutting down handler
2023-09-16 08:15:15,611 DEBUG   SenderThread:9248 [sender.py:send():388] Record cancelled: run
2023-09-16 08:15:15,611 INFO    SenderThread:9248 [sender.py:finish():1531] shutting down sender
2023-09-16 08:15:15,765 INFO    WriterThread:9248 [datastore.py:close():294] close: c:\Users\calle\Documents\GitHub\robust-rl\cliff_car\wandb\run-20230916_081342-e3nu31vx\run-e3nu31vx.wandb
